<?xml version="1.0" ?>
<robot name="JetBot">
  <property name="M_PI_2" value="1.570796327"/>

  <joint name="JetBot__left_wheel_hinge" type="continuous">
    <parent link="JetBot__chassis"/>
    <child link="JetBot__left_wheel"/>
    <origin rpy="0       0       1.57079" xyz="0.03     0.05125  0.03"/>
    <axis xyz="1  0  0"/>
  </joint>

  <transmission name="tran_jetbot_left_wheel_hinge">
    <type>transmission_interface/SimpleTransmission</type>
    <joint name="JetBot__left_wheel_hinge">
      <hardwareInterface>hardware_interface/VelocityJointInterface</hardwareInterface>
    </joint>
    <actuator name="motor_left_wheel">
      <mechanicalReduction>1</mechanicalReduction>
      <hardwareInterface>VelocityJointInterface</hardwareInterface>
    </actuator>
  </transmission>

  <joint name="JetBot__right_wheel_hinge" type="continuous">
    <parent link="JetBot__chassis"/>
    <child link="JetBot__right_wheel"/>
    <origin rpy="0       0       1.57079" xyz="0.03   -0.0595  0.03"/>
    <axis xyz="1  0  0"/>
  </joint>

  <transmission name="tran_jetbot_right_wheel_hinge">
    <type>transmission_interface/SimpleTransmission</type>
    <joint name="JetBot__right_wheel_hinge">
      <hardwareInterface>hardware_interface/VelocityJointInterface</hardwareInterface>
    </joint>
    <actuator name="motor_right_wheel">
      <mechanicalReduction>1</mechanicalReduction>
    </actuator>
  </transmission>

  <joint name="camera_joint" type="fixed">
    <parent link="JetBot__chassis"/>
    <child link="camera_link"/>
    <origin rpy="0    0.25  0" xyz="0.055   0      0.2"/>
    <axis xyz="0.96891  0       0.2474"/>
  </joint>

  <link name="JetBot__chassis">
    <inertial>
      <mass value="1.0"/>
      <origin rpy="0  0  0" xyz="0  0  0"/>
      <inertia ixx="1e-3" ixy="0" ixz="0" iyy="1e-3" iyz="0" izz="1e-3"/>
    </inertial>
    <collision name="JetBot__collision">
      <origin rpy="1.57079  0       1.57079" xyz="0     0     0.043"/>
      <geometry>
        <mesh filename="package://jetbot_description/meshes/JetBot-v3-Chassis.dae" scale="0.001 0.001 0.001"/>
      </geometry>
    </collision>
    <visual name="JetBot__visual">
      <origin rpy="1.57079  0       1.57079" xyz="0     0     0.043"/>
      <geometry>
        <mesh filename="package://jetbot_description/meshes/JetBot-v3-Chassis.dae" scale="0.001 0.001 0.001"/>
      </geometry>
    </visual>
  </link>

  <link name="JetBot__left_wheel">
    <inertial>
      <mass value="0.1"/>
      <origin rpy="0  0  0" xyz="0  0  0"/>
      <inertia ixx="1e-3" ixy="0" ixz="0" iyy="1e-3" iyz="0" izz="1e-3"/>
    </inertial>
    <collision name="JetBot__collision">
      <origin rpy="0  ${M_PI_2} 0" xyz="0 0 0"/>
      <geometry>
        <cylinder radius="0.030" length="0.008"/>
      </geometry>
    </collision>
    <visual name="JetBot__visual">
      <origin rpy="0  0  0" xyz="0  0  0"/>
      <geometry>
        <mesh filename="package://jetbot_description/meshes/JetBot-v3-Wheel.stl" scale="0.001 0.001 0.001"/>
      </geometry>
    </visual>
  </link>

  <link name="JetBot__right_wheel">
    <inertial>
      <mass value="0.1"/>
      <origin rpy="0  0  0" xyz="0  0  0"/>
      <inertia ixx="1e-3" ixy="0" ixz="0" iyy="1e-3" iyz="0" izz="1e-3"/>
    </inertial>
    <collision name="JetBot__collision">
      <origin rpy="0  ${M_PI_2} 0" xyz="0 0 0"/>
      <geometry>
        <cylinder radius="0.030" length="0.008"/>
      </geometry>
    </collision>
    <visual name="JetBot__visual">
      <origin rpy="0  0  0" xyz="0  0  0"/>
      <geometry>
        <mesh filename="package://jetbot_description/meshes/JetBot-v3-Wheel.stl" scale="0.001 0.001 0.001"/>
      </geometry>
    </visual>
  </link>
  
  <link name="camera_link">
    <inertial>
      <mass value="1e-6"/>
      <origin rpy="0  0  0" xyz="0  0  0"/>
      <inertia ixx="0.5" ixy="0" ixz="0" iyy="0.5" iyz="0" izz="0.5"/>
    </inertial>
    <visual>
      <origin rpy="0  0  0" xyz="0  0  0"/>
      <geometry>
        <box size="0.001 0.001 0.001"/>
      </geometry>
    </visual>
  </link>
  
  <joint name="hokuyo_joint" type="fixed">
    <axis xyz="0   1   0" />
    <origin xyz="0  0   0.079" rpy="0   0   0"/>
    <parent link="JetBot__chassis"/>
    <child link="hokuyo_link"/>
  </joint>
  
  <!-- Hokuyo Laser -->
  <link name="hokuyo_link">
    <collision>
      <origin xyz="0 0 0" rpy="0 0 0"/>
      <geometry>
    <box size="0.01 0.01 0.01"/>
      </geometry>
    </collision>

    <visual>
      <origin xyz="0 0 0" rpy="0 0 0"/>
      <geometry>
        <mesh filename="package://jetbot_description/meshes/hokuyo.dae"/>
      </geometry>
    </visual>

    <inertial>
      <mass value="1e-6" />
      <origin xyz="0 0 0" rpy="0 0 0"/>
      <inertia ixx="0.5" ixy="0" ixz="0" iyy="0.5" iyz="0" izz="0.5" />
    </inertial>
  </link>
  
  <!-- GPS -->
  <link name="gps_link">
    <collision>
      <origin xyz="0 0 0" rpy="0 0 0"/>
      <geometry>
    <box size="0.01 0.01 0.01"/>
      </geometry>
    </collision>
    <visual>
      <origin xyz="0 0 0" rpy="0 0 0"/>
      <geometry>
        <box size="0.001 0.001 0.001"/>
      </geometry>
    </visual>
    <inertial>
      <mass value="1e-6" />
      <origin xyz="0 0 0" rpy="0 0 0"/>
      <inertia ixx="0.5" ixy="0" ixz="0" iyy="0.5" iyz="0" izz="0.5" />
    </inertial>
  </link>
  
  <joint name="gps_joint" type="fixed">
    <axis xyz="0   1   0" />
    <origin xyz="0.04  -0.06   0.04" rpy="0   0   0"/> 
    <parent link="JetBot__chassis"/>
    <child link="gps_link"/>
  </joint>
  
  <!-- ROS control plugin -->
  <gazebo>
    <plugin name="gazebo_ros_control" filename="libgazebo_ros_control.so">
      <robotNamespace>/</robotNamespace>
    </plugin>
  </gazebo>
  
  <!--Gazebo Camera Plugin-->
  <gazebo reference="camera_link">
    <sensor type="camera" name="camera1">
      <update_rate>30.0</update_rate>
      <camera name="head">
        <horizontal_fov>1.3962634</horizontal_fov>
        <image>
          <width>1280</width>
          <height>760</height>
          <format>R8G8B8</format>
        </image>
        <clip>
         <near>0.02</near>
         <far>300</far>
        </clip>
        <noise>
          <type>gaussian</type>
          <!-- Noise is sampled independently per pixel on each frame.
              That pixel's noise value is added to each of its color
              channels, which at that point lie in the range [0,1]. -->
          <mean>0.0</mean>
          <stddev>0.007</stddev>
        </noise>
      </camera>
      <plugin name="camera_controller" filename="libgazebo_ros_camera.so">
        <alwaysOn>true</alwaysOn>
        <updateRate>0.0</updateRate>
        <cameraName>camera</cameraName>
        <imageTopicName>image_raw</imageTopicName>
        <cameraInfoTopicName>camera_info</cameraInfoTopicName>
        <frameName>camera_link</frameName>
        <hackBaseline>0.07</hackBaseline>
        <distortionK1>0.0</distortionK1>
        <distortionK2>0.0</distortionK2>
        <distortionK3>0.0</distortionK3>
        <distortionT1>0.0</distortionT1>
        <distortionT2>0.0</distortionT2>
      </plugin>
    </sensor>
  </gazebo>
  
  <!-- Gazebo Hokuyo Laser Plugin -->
  <gazebo reference="hokuyo_link">
    <sensor type="gpu_ray" name="head_hokuyo_sensor">
      <pose>0 0 0 0 0 0</pose>
      <visualize>true</visualize>
      <update_rate>40</update_rate>
      <ray>
        <scan>
          <horizontal>
            <samples>100</samples>
            <resolution>1</resolution>
            <min_angle>-1.570796</min_angle>
            <max_angle>1.570796</max_angle>
          </horizontal>
        </scan>
        <range>
          <min>0.10</min>
          <max>1.20</max>
          <resolution>0.01</resolution>
        </range>
        <noise>
          <type>gaussian</type>
          <!-- Noise parameters based on published spec for Hokuyo laser
               achieving "+-30mm" accuracy at range < 10m.  A mean of 0.0m and
               stddev of 0.01m will put 99.7% of samples within 0.03m of the true
               reading. -->
          <mean>0.0</mean>
          <stddev>0.01</stddev>
        </noise>
      </ray>
      <plugin name="gazebo_ros_head_hokuyo_controller" filename="libgazebo_ros_gpu_laser.so">
        <topicName>/jetbot/laser_scan</topicName>
        <frameName>hokuyo_link</frameName>
      </plugin>
    </sensor>
  </gazebo>
  
  <!-- GPS Sensor -->
  <gazebo>
    <plugin name="gazebo_ros_gps" filename="libhector_gazebo_ros_gps.so">
      <updateRate>4.0</updateRate>
      <bodyName>gps_link</bodyName>
      <frameId>gazebo_gps</frameId>
      <topicName>/fix</topicName>
      <velocityTopicName>/fix_velocity</velocityTopicName>
      <referenceLatitude>0.0</referenceLatitude>
      <referenceLongitude>0.0</referenceLongitude>
      <referenceHeading>90</referenceHeading>
      <referenceAltitude>0.0</referenceAltitude>
      <offset>0 0 0</offset>
      <drift>0.001 0.001 0.001</drift>
      <gaussianNoise>0.05 0.05 0.05</gaussianNoise>
      <velocityDrift>0.001 0.001 0.001</velocityDrift>
      <velocityGaussianNoise>0.5 0.5 0.5</velocityGaussianNoise>
        <drift>0.001 0.001 0.001</drift>
        <gaussianNoise>0.01 0.01 0.01</gaussianNoise>
        <velocityDrift>0 0 0</velocityDrift>
        <velocityGaussianNoise>0.05 0.05 0.05</velocityGaussianNoise>
    </plugin>
  </gazebo>
  
</robot>
